Workbook

Sheet Krav og timer
A1: Tidsestimat efter MoSCoW – MUD-spil: Bliv den stærkeste troldmand
A2: Timer = programmeringstimer for én studerende på mellemniveau. Blå tal er estimater og kan rettes; totaler opdateres automatisk.
A4: Must have (M)
A5: Område | B5: Krav | C5: Timer (lav) | D5: Timer (høj)
A6: Spilsløkke, tekstvindue, kommandoer, hjælp, se, ukendte kommandoer | B6: F4.1–4.2, F4.5–4.6, NF1, NF3 | C6: 8 | D6: 12
A7: Spiller, status, død | B7: F1 | C7: 4 | D7: 6
A8: Verden som graf, rum, udgange, bevægelse | B8: F3.1–3.6 | C8: 6 | D8: 8
A9: Inventory, genstande, potions, våben (tag, læg, brug, udrust) | B9: F2.1–2.3, F4.4, F8, F9.1–9.3, F10.1–10.2 | C9: 7 | D9: 10
A10: Kamp i runder, skade, fjender, loot, XP ved sejr | B10: F5 (M), F6.1, F6.4 | C10: 10 | D10: 14
A11: Mana og formularer | B11: F7.1–7.4 | C11: 3 | D11: 4
A12: XP og niveauer | B12: F11.1–11.2 | C12: 2 | D12: 3
A13: Fasttravel | B13: F12.1 | C13: 2 | D13: 3
A14: Strategivalg og engangsvalg | B14: F13.1–13.5 | C14: 5 | D14: 7
A15: Sejr og afslutningstekst | B15: F14 | C15: 1 | D15: 2
A16: Terning | B16: F15.1–15.3 | C16: 2 | D16: 3
A17: Indhold (rum, fjender, tekster) | B17: – | C17: 4 | D17: 6
A18: Test og fejlretning | B18: – | C18: 8 | D18: 12
A19: I alt | C19: =SUM(C6:C18) -> 62 | D19: =SUM(D6:D18) -> 90
A21: Should have (S)
A22: Område | B22: Krav | C22: Timer (lav) | D22: Timer (høj)
A23: Gem og indlæs (JSON), adskilte spiller- og verdensdata | B23: Ø1–Ø3 | C23: 5 | D23: 8
A24: Verden indlæst fra datafil | B24: F3.9 | C24: 4 | D24: 6
A25: Slutboss | B25: F6.5 | C25: 3 | D25: 4
A26: Fasttravel-liste, oplåsning, spærret under kamp | B26: F12.2–12.4 | C26: 2 | D26: 2
A27: Flugt, potions i kamp, ingen udgang under kamp | B27: F5.5, F5.8, F3.7 | C27: 2 | D27: 3
A28: undersøg, formularer, kapacitet, fjendetyper, niveau-bonusser, terningfordeling | B28: F4.3, F7.6, F2.4, F6.2, F11.3, F15.4 | C28: 4 | D28: 5
A29: I alt | C29: =SUM(C23:C28) -> 20 | D29: =SUM(D23:D28) -> 28
A31: Could have (C)
A32: Område | B32: Krav | C32: Timer (lav) | D32: Timer (høj)
A33: Grafisk kort | B33: NF8 | C33: 4 | D33: 6
A34: NPC'er | B34: F4.7 | C34: 2 | D34: 3
A35: Låste udgange og nøgler | B35: F3.8 | C35: 2 | D35: 3
A36: Træning og opgraderinger | B36: F11.4 | C36: 2 | D36: 3
A37: Valg påvirker slutningen | B37: F13.6 | C37: 2 | D37: 3
A38: Resten: korte kommandoer, aggressive fjender, genopstå, mana-regeneration, potion-størrelser, våbenbonus til magi, terningmodifikatorer, mana-pris for rejse, samlet visning | B38: diverse | C38: 6 | D38: 10
A39: I alt | C39: =SUM(C33:C38) -> 18 | D39: =SUM(D33:D38) -> 28
A41: Samlet omfang
A42: Omfang | C42: Timer (lav) | D42: Timer (høj)
A43: Kun Must | C43: =C19 -> 62 | D43: =D19 -> 90
A44: Must + Should | C44: =C19+C29 -> 82 | D44: =D19+D29 -> 118
...

Sheet Uger
A1: Omregnet til uger
A2: Gule celler er antagelser, som kan rettes. Ugetal er rundet op til hele uger.
A4: Timer pr. uge i gennemsnit | B4: 4 | C4: (5 + 3) / 2 timer, jf. jeres skema
A5: Effektiv andel af skemalagt tid | B5: 0.75 | C5: Opstart, ventetid på hjælp mv. trækker ca. 25 % fra
A6: Koordineringstab i grupper | B6: 0.2 | C6: Fratrækkes kun ved mere end 1 person
A8: Gruppestørrelse (personer) | C8: 1 | E8: 3 | G8: 4
A9: Effektive udviklertimer pr. uge | C9: =C8*$B$4*$B$5*IF(C8>1,1-$B$6,1) -> 3 | E9: =E8*$B$4*$B$5*IF(E8>1,1-$B$6,1) -> 7.2 | G9: =G8*$B$4*$B$5*IF(G8>1,1-$B$6,1) -> 9.6
A11: Omfang | B11: Timer | C11: ="Uger ("&C8&" pers., fra–til)" -> Uger (1 pers., fra–til) | E11: ="Uger ("&E8&" pers., fra–til)" -> Uger (3 pers., fra–til) | G11: ="Uger ("&G8&" pers., fra–til)" -> Uger (4 pers., fra–til)
A12: Kun Must | B12: ='Krav og timer'!C43&"–"&'Krav og timer'!D43 -> 62–90 | C12: =ROUNDUP('Krav og timer'!C43/C$9,0) -> 21 | D12: =ROUNDUP('Krav og timer'!D43/C$9,0) -> 30 | E12: =ROUNDUP('Krav og timer'!C43/E$9,0) -> 9 | F12: =ROUNDUP('Krav og timer'!D43/E$9,0) -> 13 | G12: =ROUNDUP('Krav og timer'!C43/G$9,0) -> 7 | H12: =ROUNDUP('Krav og timer'!D43/G$9,0) -> 10
A13: Must + Should | B13: ='Krav og timer'!C44&"–"&'Krav og timer'!D44 -> 82–118 | C13: =ROUNDUP('Krav og timer'!C44/C$9,0) -> 28 | D13: =ROUNDUP('Krav og timer'!D44/C$9,0) -> 40 | E13: =ROUNDUP('Krav og timer'!C44/E$9,0) -> 12 | F13: =ROUNDUP('Krav og timer'!D44/E$9,0) -> 17 | G13: =ROUNDUP('Krav og timer'!C44/G$9,0) -> 9 | H13: =ROUNDUP('Krav og timer'!D44/G$9,0) -> 13
A14: Alt (M+S+C) | B14: ='Krav og timer'!C45&"–"&'Krav og timer'!D45 -> 100–146 | C14: =ROUNDUP('Krav og timer'!C45/C$9,0) -> 34 | D14: =ROUNDUP('Krav og timer'!D45/C$9,0) -> 49 | E14: =ROUNDUP('Krav og timer'!C45/E$9,0) -> 14 | F14: =ROUNDUP('Krav og timer'!D45/E$9,0) -> 21 | G14: =ROUNDUP('Krav og timer'!C45/G$9,0) -> 11 | H14: =ROUNDUP('Krav og timer'!D45/G$9,0) -> 16
A16: Sådan bør I planlægge
A17: Start med Must og i den rigtige rækkefølge: spilsløkke, kommandoer, rum og spiller først. De første 2–3 uger kan ikke deles helt ud parallelt.
A18: Behandl Should og Could som buffer: planlæg ud fra Must + Should. Gem/indlæs og verden fra datafil giver mest værdi af Should-kravene. Kortet (NF8) er det dyreste Could-krav og det første, I kan droppe.
A19: Klassediagrammet dækker hele scopet, også Could-ting som NPC, kort, nøgler og genopstå. Implementér kun Must-klasser og -metoder i første omgang.
